<sdf version='1.7'>
  <model name='tilthex'>
    <pose>0 0 0.26 0 0 0.0</pose>
    <link name='base_link'>
      <pose>0 0 0 0 0 0</pose>
      <inertial>
        <!-- rear reference point X: -100.044mm, CAD offset: 1001.049mm -->
        <!-- top reference point Z: 33.8663mm, CAD offset: 42.8698mm -->
        <pose>0.001005 0 -0.0090035 0 0 0</pose>
        <mass>2.02</mass>
        <inertia>
          <ixx>0.011</ixx>
          <ixy>0</ixy>
          <ixz>0</ixz>
          <iyy>0.015</iyy>
          <iyz>0</iyz>
          <izz>0.021</izz>
        </inertia>
      </inertial>
      <collision name='base_link_collision'>
        <pose>0 0 0.0 0 0 0</pose>
        <geometry>
          <box>
            <size>0.67 0.67 0.15</size>
          </box>
        </geometry>
        <surface>
          <contact>
            <ode>
              <min_depth>0.001</min_depth>
              <max_vel>0</max_vel>
            </ode>
          </contact>
          <friction>
            <ode/>
          </friction>
        </surface>
      </collision>
      <visual name='base_link_visual'>
        <pose>0 0 0 0 -0 0</pose>
        <geometry>
          <mesh>
            <scale>1 1 1</scale>
            <uri>model://tilthex/meshes/base_link.STL</uri>
          </mesh>
        </geometry>
      </visual>
      <gravity>1</gravity>
      <velocity_decay/>
      <self_collide>0</self_collide>
    </link>
    <joint name='servo_1_joint' type='revolute'>
      <pose relative_to='base_link'>0 -0.2857 0.014 -1.5708 0 0</pose>
      <parent>base_link</parent>
      <child>servo_1</child>
      <axis>
        <xyz>0 0 -1</xyz>
        <limit>
          <lower>-1.5</lower>
          <upper>1.5</upper>
        </limit>
        <dynamics>
          <spring_reference>0</spring_reference>
          <spring_stiffness>0</spring_stiffness>
        </dynamics>
      </axis>
    </joint>
    <link name='servo_1'>
      <pose relative_to='servo_1_joint'>0 0 0 0 -0 0</pose>
      <inertial>
        <pose>0.000305 -0.0145 0.000688 0 -0 0</pose>
        <mass>0.017333</mass>
        <inertia>
          <ixx>0.0166704</ixx>
          <ixy>0</ixy>
          <ixz>0</ixz>
          <iyy>0.0166704</iyy>
          <iyz>0</iyz>
          <izz>0.0167604</izz>
        </inertia>
      </inertial>
      <collision name='servo_1_collision'>
        <pose>0 0 0 0 -0 0</pose>
        <geometry>
          <mesh>
            <scale>1 1 1</scale>
            <uri>model://tilthex/meshes/servo_1.STL</uri>
          </mesh>
        </geometry>
      </collision>
      <visual name='servo_1_visual'>
        <pose>0 0 0 0 -0 0</pose>
        <geometry>
          <mesh>
            <scale>1 1 1</scale>
            <uri>model://tilthex/meshes/servo_1.STL</uri>
          </mesh>
        </geometry>
      </visual>
    </link>
    <joint name='rotor_1_joint' type='revolute'>
      <pose relative_to='servo_1'>0 -0.0563 0 1.5708 -0 0</pose>
      <parent>servo_1</parent>
      <child>rotor_1</child>
      <axis>
        <xyz>0 0 1</xyz>
        <limit>
          <lower>-1e+16</lower>
          <upper>1e+16</upper>
        </limit>
        <dynamics>
          <spring_reference>0</spring_reference>
          <spring_stiffness>0</spring_stiffness>
        </dynamics>
      </axis>
    </joint>
    <link name='rotor_1'>
      <pose relative_to='rotor_1_joint'>0 0 0 0 -0 0</pose>
      <inertial>
        <pose>0 -0 -0.023377 0 -0 0</pose>
        <mass>0.019345</mass>
        <inertia>
          <ixx>9.75e-07</ixx>
          <ixy>0</ixy>
          <ixz>0</ixz>
          <iyy>0.000166704</iyy>
          <iyz>0</iyz>
          <izz>0.000167604</izz>
        </inertia>
      </inertial>
      <collision name='rotor_1_collision'>
        <pose>0 0 0 0 -0 0</pose>
        <geometry>
          <mesh>
            <scale>1 1 1</scale>
            <uri>model://tilthex/meshes/rotor_1.STL</uri>
          </mesh>
        </geometry>
      </collision>
      <visual name='rotor_1_visual'>
        <pose>0 0 0 0 -0 0</pose>
        <geometry>
          <mesh>
            <scale>1 1 1</scale>
            <uri>model://tilthex/meshes/rotor_1.STL</uri>
          </mesh>
        </geometry>
        <material>
          <script>
            <name>Gazebo/Red</name>
          </script>
        </material>
      </visual>
    </link>
    <joint name='servo_2_joint' type='revolute'>
      <pose relative_to='base_link'>-0.24742 -0.14285 0.014 -1.5708 -0 -1.0472</pose>
      <parent>base_link</parent>
      <child>servo_2</child>
      <axis>
        <xyz>0 0 -1</xyz>
        <limit>
          <lower>-1.5</lower>
          <upper>1.5</upper>
        </limit>
        <dynamics>
          <spring_reference>0</spring_reference>
          <spring_stiffness>0</spring_stiffness>
        </dynamics>
      </axis>
    </joint>
    <link name='servo_2'>
      <pose relative_to='servo_2_joint'>0 0 0 0 -0 0</pose>
      <inertial>
        <pose>0.000305 -0.0145 0.000688 0 -0 0</pose>
        <mass>0.017333</mass>
        <inertia>
          <ixx>0.0166704</ixx>
          <ixy>0</ixy>
          <ixz>0</ixz>
          <iyy>0.0166704</iyy>
          <iyz>0</iyz>
          <izz>0.0167604</izz>
        </inertia>
      </inertial>
      <collision name='servo_2_collision'>
        <pose>0 0 0 0 -0 0</pose>
        <geometry>
          <mesh>
            <scale>1 1 1</scale>
            <uri>model://tilthex/meshes/servo_2.STL</uri>
          </mesh>
        </geometry>
      </collision>
      <visual name='servo_2_visual'>
        <pose>0 0 0 0 -0 0</pose>
        <geometry>
          <mesh>
            <scale>1 1 1</scale>
            <uri>model://tilthex/meshes/servo_2.STL</uri>
          </mesh>
        </geometry>
        </visual>
    </link>
    <joint name='rotor_2_joint' type='revolute'>
      <pose relative_to='servo_2'>0 -0.0563 0 1.5708 -0 0</pose>
      <parent>servo_2</parent>
      <child>rotor_2</child>
      <axis>
        <xyz>0 0 1</xyz>
        <limit>
          <lower>-1e+16</lower>
          <upper>1e+16</upper>
        </limit>
        <dynamics>
          <spring_reference>0</spring_reference>
          <spring_stiffness>0</spring_stiffness>
        </dynamics>
      </axis>
    </joint>
    <link name='rotor_2'>
      <pose relative_to='rotor_2_joint'>0 0 0 0 -0 0</pose>
      <inertial>
        <pose>-0 -0 -0.023412 0 -0 0</pose>
        <mass>0.019252</mass>
        <inertia>
          <ixx>9.75e-07</ixx>
          <ixy>0</ixy>
          <ixz>0</ixz>
          <iyy>0.000166704</iyy>
          <iyz>0</iyz>
          <izz>0.000167604</izz>
        </inertia>
      </inertial>
      <collision name='rotor_2_collision'>
        <pose>0 0 0 0 -0 0</pose>
        <geometry>
          <mesh>
            <scale>1 1 1</scale>
            <uri>model://tilthex/meshes/rotor_2.STL</uri>
          </mesh>
        </geometry>
      </collision>
      <visual name='rotor_2_visual'>
        <pose>0 0 0 0 -0 0</pose>
        <geometry>
          <mesh>
            <scale>1 1 1</scale>
            <uri>model://tilthex/meshes/rotor_2.STL</uri>
          </mesh>
        </geometry>
      </visual>
    </link>
    <joint name='servo_3_joint' type='revolute'>
      <pose relative_to='base_link'>-0.24742 0.14285 0.014 -1.5708 -0 -2.0944</pose>
      <parent>base_link</parent>
      <child>servo_3</child>
      <axis>
        <xyz>0 0 -1</xyz>
        <limit>
          <lower>-1.5</lower>
          <upper>1.5</upper>
        </limit>
        <dynamics>
          <spring_reference>0</spring_reference>
          <spring_stiffness>0</spring_stiffness>
        </dynamics>
      </axis>
    </joint>
    <link name='servo_3'>
      <pose relative_to='servo_3_joint'>0 0 0 0 -0 0</pose>
      <inertial>
        <pose>0.000305 -0.0145 0.000688 0 -0 0</pose>
        <mass>0.017333</mass>
        <inertia>
          <ixx>0.0166704</ixx>
          <ixy>0</ixy>
          <ixz>0</ixz>
          <iyy>0.0166704</iyy>
          <iyz>0</iyz>
          <izz>0.0167604</izz>
        </inertia>
      </inertial>
      <collision name='servo_3_collision'>
        <pose>0 0 0 0 -0 0</pose>
        <geometry>
          <mesh>
            <scale>1 1 1</scale>
            <uri>model://tilthex/meshes/servo_3.STL</uri>
          </mesh>
        </geometry>
      </collision>
      <visual name='servo_3_visual'>
        <pose>0 0 0 0 -0 0</pose>
        <geometry>
          <mesh>
            <scale>1 1 1</scale>
            <uri>model://tilthex/meshes/servo_3.STL</uri>
          </mesh>
        </geometry>
      </visual>
    </link>
    <joint name='rotor_3_joint' type='revolute'>
      <pose relative_to='servo_3'>0 -0.0563 0 1.5708 -0 0</pose>
      <parent>servo_3</parent>
      <child>rotor_3</child>
      <axis>
        <xyz>0 0 1</xyz>
        <limit>
          <lower>-1e+16</lower>
          <upper>1e+16</upper>
        </limit>
        <dynamics>
          <spring_reference>0</spring_reference>
          <spring_stiffness>0</spring_stiffness>
        </dynamics>
      </axis>
    </joint>
    <link name='rotor_3'>
      <pose relative_to='rotor_3_joint'>0 0 0 0 -0 0</pose>
      <inertial>
        <pose>-0 0 -0.023377 0 -0 0</pose>
        <mass>0.019345</mass>
        <inertia>
          <ixx>9.75e-07</ixx>
          <ixy>0</ixy>
          <ixz>0</ixz>
          <iyy>0.000166704</iyy>
          <iyz>0</iyz>
          <izz>0.000167604</izz>
        </inertia>
      </inertial>
      <collision name='rotor_3_collision'>
        <pose>0 0 0 0 -0 0</pose>
        <geometry>
          <mesh>
            <scale>1 1 1</scale>
            <uri>model://tilthex/meshes/rotor_3.STL</uri>
          </mesh>
        </geometry>
      </collision>
      <visual name='rotor_3_visual'>
        <pose>0 0 0 0 -0 0</pose>
        <geometry>
          <mesh>
            <scale>1 1 1</scale>
            <uri>model://tilthex/meshes/rotor_3.STL</uri>
          </mesh>
        </geometry>
        <material>
      <script>
        <name>Gazebo/Blue</name>
        <uri>__default__</uri>
      </script>
      </material>
      </visual>
    </link>
    <joint name='servo_4_joint' type='revolute'>
      <pose relative_to='base_link'>0 0.2857 0.014 -1.5708 -0 3.14159</pose>
      <parent>base_link</parent>
      <child>servo_4</child>
      <axis>
        <xyz>0 0 -1</xyz>
        <limit>
          <lower>-1.5</lower>
          <upper>1.5</upper>
        </limit>
        <dynamics>
          <spring_reference>0</spring_reference>
          <spring_stiffness>0</spring_stiffness>
        </dynamics>
      </axis>
    </joint>
    <link name='servo_4'>
      <pose relative_to='servo_4_joint'>0 0 0 0 -0 0</pose>
      <inertial>
        <pose>0.000305 -0.0145 0.000688 0 -0 0</pose>
        <mass>0.017333</mass>
        <inertia>
          <ixx>0.0166704</ixx>
          <ixy>0</ixy>
          <ixz>0</ixz>
          <iyy>0.0166704</iyy>
          <iyz>0</iyz>
          <izz>0.0167604</izz>
        </inertia>
      </inertial>
      <collision name='servo_4_collision'>
        <pose>0 0 0 0 -0 0</pose>
        <geometry>
          <mesh>
            <scale>1 1 1</scale>
            <uri>model://tilthex/meshes/servo_4.STL</uri>
          </mesh>
        </geometry>
      </collision>
      <visual name='servo_4_visual'>
        <pose>0 0 0 0 -0 0</pose>
        <geometry>
          <mesh>
            <scale>1 1 1</scale>
            <uri>model://tilthex/meshes/servo_4.STL</uri>
          </mesh>
        </geometry>
      </visual>
    </link>
    <joint name='rotor_4_joint' type='revolute'>
      <pose relative_to='servo_4'>0 -0.0563 0 1.5708 -0 0</pose>
      <parent>servo_4</parent>
      <child>rotor_4</child>
      <axis>
        <xyz>0 0 1</xyz>
        <limit>
          <lower>-1e+16</lower>
          <upper>1e+16</upper>
        </limit>
        <dynamics>
          <spring_reference>0</spring_reference>
          <spring_stiffness>0</spring_stiffness>
        </dynamics>
      </axis>
    </joint>
    <link name='rotor_4'>
      <pose relative_to='rotor_4_joint'>0 0 0 0 -0 0</pose>
      <inertial>
        <pose>0 -0 -0.023412 0 -0 0</pose>
        <mass>0.019252</mass>
        <inertia>
          <ixx>9.75e-07</ixx>
          <ixy>0</ixy>
          <ixz>0</ixz>
          <iyy>0.000166704</iyy>
          <iyz>0</iyz>
          <izz>0.000167604</izz>
        </inertia>
      </inertial>
      <collision name='rotor_4_collision'>
        <pose>0 0 0 0 -0 0</pose>
        <geometry>
          <mesh>
            <scale>1 1 1</scale>
            <uri>model://tilthex/meshes/rotor_4.STL</uri>
          </mesh>
        </geometry>
      </collision>
      <visual name='rotor_4_visual'>
        <pose>0 0 0 0 -0 0</pose>
        <geometry>
          <mesh>
            <scale>1 1 1</scale>
            <uri>model://tilthex/meshes/rotor_4.STL</uri>
          </mesh>
        </geometry>
      </visual>
    </link>
    <joint name='servo_5_joint' type='revolute'>
      <pose relative_to='base_link'>0.24742 0.14285 0.014 -1.5708 0 2.0944</pose>
      <parent>base_link</parent>
      <child>servo_5</child>
      <axis>
        <xyz>0 0 -1</xyz>
        <limit>
          <lower>-1.5</lower>
          <upper>1.5</upper>
        </limit>
        <dynamics>
          <spring_reference>0</spring_reference>
          <spring_stiffness>0</spring_stiffness>
        </dynamics>
      </axis>
    </joint>
    <link name='servo_5'>
      <pose relative_to='servo_5_joint'>0 0 0 0 -0 0</pose>
      <inertial>
        <pose>0.000305 -0.0145 0.000688 0 -0 0</pose>
        <mass>0.017333</mass>
        <inertia>
          <ixx>0.0166704</ixx>
          <ixy>0</ixy>
          <ixz>0</ixz>
          <iyy>0.0166704</iyy>
          <iyz>0</iyz>
          <izz>0.0167604</izz>
        </inertia>
      </inertial>
      <collision name='servo_5_collision'>
        <pose>0 0 0 0 -0 0</pose>
        <geometry>
          <mesh>
            <scale>1 1 1</scale>
            <uri>model://tilthex/meshes/servo_5.STL</uri>
          </mesh>
        </geometry>
      </collision>
      <visual name='servo_5_visual'>
        <pose>0 0 0 0 -0 0</pose>
        <geometry>
          <mesh>
            <scale>1 1 1</scale>
            <uri>model://tilthex/meshes/servo_5.STL</uri>
          </mesh>
        </geometry>
      </visual>
    </link>
    <joint name='rotor_5_joint' type='revolute'>
      <pose relative_to='servo_5'>0 -0.0563 0 1.5708 -0 0</pose>
      <parent>servo_5</parent>
      <child>rotor_5</child>
      <axis>
        <xyz>0 0 1</xyz>
        <limit>
          <lower>-1e+16</lower>
          <upper>1e+16</upper>
        </limit>
        <dynamics>
          <spring_reference>0</spring_reference>
          <spring_stiffness>0</spring_stiffness>
        </dynamics>
      </axis>
    </joint>
    <link name='rotor_5'>
      <pose relative_to='rotor_5_joint'>0 0 0 0 -0 0</pose>
      <inertial>
        <pose>-0 -0 -0.023377 0 -0 0</pose>
        <mass>0.019345</mass>
        <inertia>
          <ixx>9.75e-07</ixx>
          <ixy>0</ixy>
          <ixz>0</ixz>
          <iyy>0.000166704</iyy>
          <iyz>0</iyz>
          <izz>0.000167604</izz>
        </inertia>
      </inertial>
      <collision name='rotor_5_collision'>
        <pose>0 0 0 0 -0 0</pose>
        <geometry>
          <mesh>
            <scale>1 1 1</scale>
            <uri>model://tilthex/meshes/rotor_5.STL</uri>
          </mesh>
        </geometry>
      </collision>
      <visual name='rotor_5_visual'>
        <pose>0 0 0 0 -0 0</pose>
        <geometry>
          <mesh>
            <scale>1 1 1</scale>
            <uri>model://tilthex/meshes/rotor_5.STL</uri>
          </mesh>
        </geometry>
        <material>
          <script>
            <name>Gazebo/Blue</name>
          </script>
        </material>
      </visual>
    </link>
    <joint name='servo_6_joint' type='revolute'>
      <pose relative_to='base_link'>0.24742 -0.14285 0.014 -1.5708 -0 1.0472</pose>
      <parent>base_link</parent>
      <child>servo_6</child>
      <axis>
        <xyz>0 0 -1</xyz>
        <limit>
          <lower>-1.5</lower>
          <upper>1.5</upper>
        </limit>
        <dynamics>
          <spring_reference>0</spring_reference>
          <spring_stiffness>0</spring_stiffness>
        </dynamics>
      </axis>
    </joint>
    <link name='servo_6'>
      <pose relative_to='servo_6_joint'>0 0 0 0 -0 0</pose><!-- relative_to='6' -->
      <inertial>
        <pose>0.000305 -0.0145 0.000688 0 -0 0</pose>
        <mass>0.017333</mass>
        <inertia>
          <ixx>0.0166704</ixx>
          <ixy>0</ixy>
          <ixz>0</ixz>
          <iyy>0.0166704</iyy>
          <iyz>0</iyz>
          <izz>0.0167604</izz>
        </inertia>
      </inertial>
      <collision name='servo_6_collision'>
        <pose>0 0 0 0 -0 0</pose>
        <geometry>
          <mesh>
            <scale>1 1 1</scale>
            <uri>model://tilthex/meshes/servo_6.STL</uri>
          </mesh>
        </geometry>
      </collision>
      <visual name='servo_6_visual'>
        <pose>0 0 0 0 -0 0</pose>
        <geometry>
          <mesh>
            <scale>1 1 1</scale>
            <uri>model://tilthex/meshes/servo_6.STL</uri>
          </mesh>
        </geometry>
      </visual>
    </link>
    <joint name='rotor_6_joint' type='revolute'>
      <pose relative_to='servo_6'>0 -0.0563 0 1.5708 -0 0</pose>
      <parent>servo_6</parent>
      <child>rotor_6</child>
      <axis>
        <xyz>0 0 1</xyz>
        <limit>
          <lower>-1e+16</lower>
          <upper>1e+16</upper>
        </limit>
        <dynamics>
          <spring_reference>0</spring_reference>
          <spring_stiffness>0</spring_stiffness>
        </dynamics>
      </axis>
    </joint>
    <link name='rotor_6'>
      <pose relative_to='rotor_6_joint'>0 0 0 0 -0 0</pose>
      <inertial>
        <pose>-0 -0 -0.023412 0 -0 0</pose>
        <mass>0.019252</mass>
        <inertia>
          <ixx>9.75e-07</ixx>
          <ixy>0</ixy>
          <ixz>0</ixz>
          <iyy>0.000273104</iyy>
          <iyz>0</iyz>
          <izz>0.000274004</izz>
        </inertia>
      </inertial>
      <collision name='rotor_6_collision'>
        <pose>0 0 0 0 -0 0</pose>
        <geometry>
          <mesh>
            <scale>1 1 1</scale>
            <uri>model://tilthex/meshes/rotor_6.STL</uri>
          </mesh>
        </geometry>
      </collision>
      <visual name='rotor_6_visual'>
        <pose>0 0 0 0 -0 0</pose>5
        <geometry>
          <mesh>
            <scale>1 1 1</scale>
            <uri>model://tilthex/meshes/rotor_6.STL</uri>
          </mesh>
        </geometry>
      </visual>
    </link>

    <link name='imu_link'>
      <pose>0 0 0 0 -0 0</pose>
      <inertial>
        <pose>0 0 0 0 -0 0</pose>
        <mass>0.015</mass>
        <inertia>
          <ixx>1e-05</ixx>
          <ixy>0</ixy>
          <ixz>0</ixz>
          <iyy>1e-05</iyy>
          <iyz>0</iyz>
          <izz>1e-05</izz>
        </inertia>
      </inertial>
    </link>
    <joint name='imu_joint' type='revolute'>
      <child>imu_link</child>
      <parent>base_link</parent>
      <axis>
        <xyz>1 0 0</xyz>
        <limit>
          <lower>0</lower>
          <upper>0</upper>
          <effort>0</effort>
          <velocity>0</velocity>
        </limit>
        <dynamics>
          <spring_reference>0</spring_reference>
          <spring_stiffness>0</spring_stiffness>
        </dynamics>
        <use_parent_model_frame>1</use_parent_model_frame>
      </axis>
    </joint>
    <include>
      <uri>model://gps</uri>
      <pose>0 0 0 0 0 0</pose>
      <name>gps</name>
    </include>
    <joint name='gps_joint' type='fixed'>
      <child>gps::link</child>
      <parent>base_link</parent>
    </joint>

    <plugin name='gazebo_imu_plugin' filename='libgazebo_imu_plugin.so'>
      <robotNamespace></robotNamespace>
      <linkName>imu_link</linkName>
      <imuTopic>/imu</imuTopic>
      <gyroscopeNoiseDensity>0.0003394</gyroscopeNoiseDensity>
      <gyroscopeRandomWalk>3.8785e-05</gyroscopeRandomWalk>
      <gyroscopeBiasCorrelationTime>1000.0</gyroscopeBiasCorrelationTime>
      <gyroscopeTurnOnBiasSigma>0.0087</gyroscopeTurnOnBiasSigma>
      <accelerometerNoiseDensity>0.004</accelerometerNoiseDensity>
      <accelerometerRandomWalk>0.006</accelerometerRandomWalk>
      <accelerometerBiasCorrelationTime>300.0</accelerometerBiasCorrelationTime>
      <accelerometerTurnOnBiasSigma>0.196</accelerometerTurnOnBiasSigma>
    </plugin>

    <plugin name='front_right_motor_model' filename='libgazebo_motor_model.so'>
      <robotNamespace></robotNamespace>
      <jointName>rotor_3_joint</jointName>
      <linkName>rotor_3</linkName>
      <turningDirection>ccw</turningDirection>
      <timeConstantUp>0.0125</timeConstantUp>
      <timeConstantDown>0.025</timeConstantDown>
      <maxRotVelocity>1500</maxRotVelocity>
      <motorConstant>8.54858e-06</motorConstant>
      <momentConstant>0.06</momentConstant>
      <commandSubTopic>/gazebo/command/motor_speed</commandSubTopic>
      <motorNumber>3</motorNumber>
      <rotorDragCoefficient>0.000806428</rotorDragCoefficient>
      <rollingMomentCoefficient>1e-06</rollingMomentCoefficient>
      <motorSpeedPubTopic>/motor_speed/5</motorSpeedPubTopic>
      <rotorVelocitySlowdownSim>10</rotorVelocitySlowdownSim>
    </plugin>
    <plugin name='back_left_motor_model' filename='libgazebo_motor_model.so'>
      <robotNamespace></robotNamespace>
      <jointName>rotor_6_joint</jointName>
      <linkName>rotor_6</linkName>
      <turningDirection>cw</turningDirection>
      <timeConstantUp>0.0125</timeConstantUp>
      <timeConstantDown>0.025</timeConstantDown>
      <maxRotVelocity>1500</maxRotVelocity>
      <motorConstant>8.54858e-06</motorConstant>
      <momentConstant>0.06</momentConstant>
      <commandSubTopic>/gazebo/command/motor_speed</commandSubTopic>
      <motorNumber>0</motorNumber>
      <rotorDragCoefficient>0.000806428</rotorDragCoefficient>
      <rollingMomentCoefficient>1e-06</rollingMomentCoefficient>
      <motorSpeedPubTopic>/motor_speed/4</motorSpeedPubTopic>
      <rotorVelocitySlowdownSim>10</rotorVelocitySlowdownSim>
    </plugin>
    <plugin name='front_left_motor_model' filename='libgazebo_motor_model.so'>
      <robotNamespace></robotNamespace>
      <jointName>rotor_2_joint</jointName>
      <linkName>rotor_2</linkName>
      <turningDirection>cw</turningDirection>
      <timeConstantUp>0.0125</timeConstantUp>
      <timeConstantDown>0.025</timeConstantDown>
      <maxRotVelocity>1500</maxRotVelocity>
      <motorConstant>8.54858e-06</motorConstant>
      <momentConstant>0.06</momentConstant>
      <commandSubTopic>/gazebo/command/motor_speed</commandSubTopic>
      <motorNumber>4</motorNumber>
      <rotorDragCoefficient>0.000806428</rotorDragCoefficient>
      <rollingMomentCoefficient>1e-06</rollingMomentCoefficient>
      <motorSpeedPubTopic>/motor_speed/3</motorSpeedPubTopic>
      <rotorVelocitySlowdownSim>10</rotorVelocitySlowdownSim>
    </plugin>
    <plugin name='back_right_motor_model' filename='libgazebo_motor_model.so'>
      <robotNamespace></robotNamespace>
      <jointName>rotor_5_joint</jointName>
      <linkName>rotor_5</linkName>
      <turningDirection>ccw</turningDirection>
      <timeConstantUp>0.0125</timeConstantUp>
      <timeConstantDown>0.025</timeConstantDown>
      <maxRotVelocity>1500</maxRotVelocity>
      <motorConstant>8.54858e-06</motorConstant>
      <momentConstant>0.06</momentConstant>
      <commandSubTopic>/gazebo/command/motor_speed</commandSubTopic>
      <motorNumber>1</motorNumber>
      <rotorDragCoefficient>0.000806428</rotorDragCoefficient>
      <rollingMomentCoefficient>1e-06</rollingMomentCoefficient>
      <motorSpeedPubTopic>/motor_speed/2</motorSpeedPubTopic>
      <rotorVelocitySlowdownSim>10</rotorVelocitySlowdownSim>
    </plugin>
    <plugin name='back_left_motor_model' filename='libgazebo_motor_model.so'>
      <robotNamespace></robotNamespace>
      <jointName>rotor_4_joint</jointName>
      <linkName>rotor_4</linkName>
      <turningDirection>cw</turningDirection>
      <timeConstantUp>0.0125</timeConstantUp>
      <timeConstantDown>0.025</timeConstantDown>
      <maxRotVelocity>1500</maxRotVelocity>
      <motorConstant>8.54858e-06</motorConstant>
      <momentConstant>0.06</momentConstant>
      <commandSubTopic>/gazebo/command/motor_speed</commandSubTopic>
      <motorNumber>2</motorNumber>
      <rotorDragCoefficient>0.000806428</rotorDragCoefficient>
      <rollingMomentCoefficient>1e-06</rollingMomentCoefficient>
      <motorSpeedPubTopic>/motor_speed/1</motorSpeedPubTopic>
      <rotorVelocitySlowdownSim>10</rotorVelocitySlowdownSim>
    </plugin>
    <plugin name='front_left_motor_model' filename='libgazebo_motor_model.so'>
      <robotNamespace></robotNamespace>
      <jointName>rotor_1_joint</jointName>
      <linkName>rotor_1</linkName>
      <turningDirection>ccw</turningDirection>
      <timeConstantUp>0.0125</timeConstantUp>
      <timeConstantDown>0.025</timeConstantDown>
      <maxRotVelocity>1500</maxRotVelocity>
      <motorConstant>8.54858e-06</motorConstant>
      <momentConstant>0.06</momentConstant>
      <commandSubTopic>/gazebo/command/motor_speed</commandSubTopic>
      <motorNumber>5</motorNumber>
      <rotorDragCoefficient>0.000806428</rotorDragCoefficient>
      <rollingMomentCoefficient>1e-06</rollingMomentCoefficient>
      <motorSpeedPubTopic>/motor_speed/0</motorSpeedPubTopic>
      <rotorVelocitySlowdownSim>10</rotorVelocitySlowdownSim>
    </plugin>
    <plugin name='groundtruth_plugin' filename='libgazebo_groundtruth_plugin.so'>
      <robotNamespace/>
    </plugin>
    <plugin name='magnetometer_plugin' filename='libgazebo_magnetometer_plugin.so'>
      <robotNamespace/>
      <pubRate>100</pubRate>
      <noiseDensity>0.0004</noiseDensity>
      <randomWalk>6.4e-06</randomWalk>
      <biasCorrelationTime>600</biasCorrelationTime>
      <magTopic>/mag</magTopic>
    </plugin>
    <plugin name='barometer_plugin' filename='libgazebo_barometer_plugin.so'>
      <robotNamespace/>
      <pubRate>50</pubRate>
      <baroTopic>/baro</baroTopic>
    </plugin>
    <plugin name='mavlink_interface' filename='libgazebo_mavlink_interface.so'>
      <robotNamespace></robotNamespace>
      <imuSubTopic>/imu</imuSubTopic>
      <magSubTopic>/mag</magSubTopic>
      <baroSubTopic>/baro</baroSubTopic>
      <mavlink_addr>INADDR_ANY</mavlink_addr>
      <mavlink_tcp_port>4560</mavlink_tcp_port>
      <mavlink_udp_port>14560</mavlink_udp_port>
      <serialEnabled>0</serialEnabled>
      <serialDevice>/dev/ttyACM0</serialDevice>
      <baudRate>921600</baudRate>
      <qgc_addr>INADDR_ANY</qgc_addr>
      <qgc_udp_port>14550</qgc_udp_port>
      <sdk_addr>INADDR_ANY</sdk_addr>
      <sdk_udp_port>14540</sdk_udp_port>
      <hil_mode>0</hil_mode>
      <hil_state_level>false</hil_state_level>
      <enable_lockstep>true</enable_lockstep>
      <use_tcp>true</use_tcp>
      <motorSpeedCommandPubTopic>/gazebo/command/motor_speed</motorSpeedCommandPubTopic>
      <control_channels>
        <channel name="rotor0">
          <input_index>0</input_index>
          <input_offset>0</input_offset>
          <input_scaling>1500</input_scaling>
          <zero_position_disarmed>0</zero_position_disarmed>
          <zero_position_armed>1</zero_position_armed>
          <joint_control_type>velocity</joint_control_type>
        </channel>
        <channel name="rotor1">
          <input_index>1</input_index>
          <input_offset>0</input_offset>
          <input_scaling>1500</input_scaling>
          <zero_position_disarmed>0</zero_position_disarmed>
          <zero_position_armed>1</zero_position_armed>
          <joint_control_type>velocity</joint_control_type>
        </channel>
        <channel name="rotor2">
          <input_index>2</input_index>
          <input_offset>0</input_offset>
          <input_scaling>1500</input_scaling>
          <zero_position_disarmed>0</zero_position_disarmed>
          <zero_position_armed>1</zero_position_armed>
          <joint_control_type>velocity</joint_control_type>
        </channel>
        <channel name="rotor3">
          <input_index>3</input_index>
          <input_offset>0</input_offset>
          <input_scaling>1500</input_scaling>
          <zero_position_disarmed>0</zero_position_disarmed>
          <zero_position_armed>1</zero_position_armed>
          <joint_control_type>velocity</joint_control_type>
        </channel>
        <channel name="rotor4">
          <input_index>4</input_index>
          <input_offset>0</input_offset>
          <input_scaling>1500</input_scaling>
          <zero_position_disarmed>10</zero_position_disarmed>
          <zero_position_armed>1</zero_position_armed>
          <joint_control_type>velocity</joint_control_type>
        </channel>
        <channel name="rotor5">
          <input_index>5</input_index>
          <input_offset>0</input_offset>
          <input_scaling>1500</input_scaling>
          <zero_position_disarmed>10</zero_position_disarmed>
          <zero_position_armed>1</zero_position_armed>
          <joint_control_type>velocity</joint_control_type>
        </channel>
         <channel name="motor1_tilt">
          <input_index>11</input_index>
          <input_offset> 0</input_offset>
          <input_scaling>1.57</input_scaling>
          <zero_position_disarmed>0</zero_position_disarmed>
          <zero_position_armed>0</zero_position_armed>
          <joint_control_type>position</joint_control_type>
          <joint_name>servo_1_joint</joint_name>
           <joint_control_pid>
            <p>10</p>
            <i>2</i>
            <d>3</d>
            <iMax>0.0</iMax>
            <iMin>0.0</iMin>
            <cmdMax>10</cmdMax>
            <cmdMin>-10</cmdMin>
            <errMax>0.2</errMax>
          </joint_control_pid>
        </channel>
        <channel name="motor2_tilt">
          <input_index>10</input_index>
          <input_offset> 0</input_offset>
          <input_scaling>1.57</input_scaling>
          <zero_position_disarmed>0</zero_position_disarmed>
          <zero_position_armed>0</zero_position_armed>
          <joint_control_type>position</joint_control_type>
          <joint_name>servo_2_joint</joint_name>
           <joint_control_pid>
            <p>10</p>
            <i>3</i>
            <d>8</d>
            <iMax>0.0</iMax>
            <iMin>0.0</iMin>
            <cmdMax>2</cmdMax>
            <cmdMin>-2</cmdMin>
            <errMax>0.2</errMax>
          </joint_control_pid>
        </channel>
        <channel name="motor3_tilt">
          <input_index>9</input_index>
          <input_offset>0</input_offset>
          <input_scaling>1.57</input_scaling>
          <zero_position_disarmed>0</zero_position_disarmed>
          <zero_position_armed>0</zero_position_armed>
          <joint_control_type>position</joint_control_type>
          <joint_name>servo_3_joint</joint_name>
           <joint_control_pid>
            <p>10</p>
            <i>1</i>
            <d>5</d>
            <iMax>0.0</iMax>
            <iMin>0.0</iMin>
            <cmdMax>2</cmdMax>
            <cmdMin>-2</cmdMin>
            <errMax>0.2</errMax>
          </joint_control_pid>
        </channel>
        <channel name="motor4_tilt">
          <input_index>8</input_index>
          <input_offset>0</input_offset>
          <input_scaling>1.57</input_scaling>
          <zero_position_disarmed>0</zero_position_disarmed>
          <zero_position_armed>0</zero_position_armed>
          <joint_control_type>position</joint_control_type>
          <joint_name>servo_4_joint</joint_name>
           <joint_control_pid>
            <p>10</p>
            <i>3</i>
            <d>8</d>
            <iMax>0.0</iMax>
            <iMin>0.0</iMin>
            <cmdMax>2</cmdMax>
            <cmdMin>-2</cmdMin>
            <errMax>0.2</errMax>
          </joint_control_pid>
        </channel>
        <channel name="motor5_tilt">
          <input_index>7</input_index>
          <input_offset>0</input_offset>
          <input_scaling>1.57</input_scaling>
          <zero_position_disarmed>0</zero_position_disarmed>
          <zero_position_armed>0</zero_position_armed>
          <joint_control_type>position</joint_control_type>
          <joint_name>servo_5_joint</joint_name>
           <joint_control_pid>
            <p>10</p>
            <i>3</i>
            <d>5</d>
            <iMax>0.0</iMax>
            <iMin>0.0</iMin>
            <cmdMax>2</cmdMax>
            <cmdMin>-2</cmdMin>
            <errMax>0.2</errMax>
          </joint_control_pid>
        </channel>
        <channel name="motor6_tilt">
          <input_index>6</input_index>
          <input_offset>0</input_offset>
          <input_scaling>1.57</input_scaling>
          <zero_position_disarmed>0</zero_position_disarmed>
          <zero_position_armed>0</zero_position_armed>
          <joint_control_type>position</joint_control_type>
          <joint_name>servo_6_joint</joint_name>
           <joint_control_pid>
            <p>10</p>
            <i>1</i>
            <d>5</d>
            <iMax>0.0</iMax>
            <iMin>0.0</iMin>
            <cmdMax>2</cmdMax>
            <cmdMin>-2</cmdMin>
            <errMax>0.2</errMax>
          </joint_control_pid>
        </channel>
       </control_channels>
    </plugin>
    </model>
</sdf>
